Workbook

Sheet 📋 Cover
B2: Oracle SE + OCI GoldenGate DB 정합성 검증 계획서
B5: Source: Oracle SE (RDS/AWS Tokyo) → Target: Oracle SE (OCI Tokyo) | Tool: OCI GoldenGate Cloud
B6: 문서 버전 | D6: v1.0 | E6: 2026-03-13
B11: ■ 검증 영역 범례
B13: 정적 구조 검증 (Static Schema) | C13: 스키마, 객체, DDL 구조 비교
B14: 데이터 정합성 (Data Validation) | C14: Row Count, Checksum, 샘플 비교
B15: LAG / 프로세스 (GG Process) | C15: Extract·Replicat LAG, Trail 상태
B16: 사전 확인 (Pre-Check) | C16: 마이그레이션 전 소스/타겟/GG 환경 점검
B17: 주의사항 (Caution) | C17: SE 제약, OCI GG 특이사항, 상시운영 포인트
B19: ■ 중요도 / 결과 범례
B21: [상] High | C21: 즉시 조치 필요, Cut-over 블로커
B22: [중] Medium | C22: 마이그레이션 전 해결 권장
B23: [하] Low | C23: 운영 안정화 후 처리 가능
B24: PASS | C24: 소스/타겟 일치
B25: FAIL | C25: 불일치 – 즉시 조치
B26: WARN | C26: 허용 오차 범위 내 – 원인 분석
B29: ■ 시트 목차
B31: ① | C31: 01_GG_Process | D31: OCI GG 프로세스 검증 (Extract/Pump/Replicat/LAG)
B32: ② | C32: 02_Static_Schema | D32: 정적 구조 검증 (테이블·뷰·인덱스·제약·시퀀스 등)
B33: ③ | C33: 03_Data_Validation | D33: 데이터 정합성 (Row Count·Checksum·LOB·특수객체)
B34: ④ | C34: 04_Special_Objects | D34: 특수 객체 (MV·Trigger·DBLink·DBMS_JOB·파티션)
B35: ⑤ | C35: 05_Migration_Caution | D35: 마이그레이션 주의사항 & SE 제약·OCI GG 특이사항
B36: ⑥ | C36: 06_Result_Dashboard | D36: 검증 결과 대시보드 (요약/판정)

Sheet 01_GG_Process
A1: NO | B1: 검증 영역 | C1: 검증 항목 | D1: 검증 방법 / 확인 내용 | E1: 중요도 | F1: SE제약 | G1: OCI GG | H1: 결과 | I1: 비고
A2: ▶ OCI GoldenGate 프로세스 & LAG 검증
A3: 1 | B3: Pre-Check | C3: ENABLE_GOLDENGATE_REPLICATION 파라미터 | D3: 소스 DB: VALUE=TRUE 확인 (SE 기본값 FALSE) | E3: 상 | F3: ⚠️ | H3: -
A4: 2 | B4: Pre-Check | C4: Archive Log 모드 확인 | D4: V$DATABASE.LOG_MODE = ARCHIVELOG 확인 | E4: 상 | H4: -
A5: 3 | B5: Pre-Check | C5: Supplemental Logging (MIN) 활성화 | D5: ALTER DATABASE ADD SUPPLEMENTAL LOG DATA 적용 확인 | E5: 상 | F5: ⚠️ | H5: -
A6: 4 | B6: Pre-Check | C6: Supplemental Logging (PK) 활성화 | D6: PK 없는 테이블 → ALL COLUMNS 로깅 설정 여부 | E6: 상 | F6: ⚠️ | H6: -
A7: 5 | B7: Pre-Check | C7: Redo Log 크기 및 그룹 수 | D7: 최소 3그룹, 그룹당 500MB 이상 권장 확인 | E7: 중 | H7: -
A8: 6 | B8: Pre-Check | C8: GGADMIN 계정 권한 | D8: DBA_ROLE_PRIVS / DBA_SYS_PRIVS 필수 권한 확인 | E8: 상 | G8: ☁️ | H8: -
A9: 7 | B9: Pre-Check | C9: RDS Redo Log 보존 기간 | D9: rdsadmin.rdsadmin_util.set_configuration 24h 이상 설정 | E9: 상 | G9: ☁️ | H9: -
A10: 8 | B10: Pre-Check | C10: OCI GG Deployment 버전 | D10: 소스 Oracle 19c 지원 버전 확인 | E10: 중 | G10: ☁️ | H10: -
A11: 9 | B11: Pre-Check | C11: 네트워크 연결 (RDS→OCI GG) | D11: 1521 | E11: 상 | G11: ☁️ | H11: -
A12: 10 | B12: Extract | C12: Extract 프로세스 상태 | D12: STATUS EXTRACT → RUNNING 확인 | E12: 상 | H12: -
A13: 11 | B13: Extract | C13: Extract LAG | D13: LAG EXTRACT < 30초 이내 유지 | E13: 상 | H13: -
A14: 12 | B14: Extract | C14: Extract Trail 파일 생성 | D14: Trail 파일 정상 생성 및 용량 증가 확인 | E14: 상 | G14: ☁️ | H14: -
A15: 13 | B15: Extract | C15: Extract Checkpoint SCN 진행 | D15: CURRENT_SCN 대비 Checkpoint SCN 비교 | E15: 중 | H15: -
A16: 14 | B16: Extract | C16: Extract ABEND 이력 | D16: VIEW REPORT → ABEND/ERROR 없음 확인 | E16: 상 | H16: -
A17: 15 | B17: Data Pump | C17: Data Pump 프로세스 상태 | D17: STATUS EXTRACT (Pump) → RUNNING | E17: 상 | G17: ☁️ | H17: -
A18: 16 | B18: Data Pump | C18: Pump LAG | D18: Trail 전송 지연 < 30초 | E18: 중 | G18: ☁️ | H18: -
A19: 17 | B19: Data Pump | C19: OCI Object Storage 연결 | D19: Pump→OCI Trail 저장소 접근 가능 여부 | E19: 중 | G19: ☁️ | H19: -
A20: 18 | B20: Replicat | C20: Replicat 프로세스 상태 | D20: STATUS REPLICAT → RUNNING 확인 | E20: 상 | H20: -
A21: 19 | B21: Replicat | C21: Replicat LAG | D21: LAG REPLICAT < 30초 이내 | E21: 상 | H21: -
A22: 20 | B22: Replicat | C22: Replicat Apply 통계 | D22: STATS REPLICAT TOTAL → Insert/Update/Delete 건수 | E22: 상 | H22: -
A23: 21 | B23: Replicat | C23: Discard 파일 레코드 | D23: Discard 파일 내 Skip된 레코드 0건 | E23: 상 | H23: -
A24: 22 | B24: Replicat | C24: SUPPRESSTRIGGERS 설정 | D24: Replicat 적용 시 타겟 Trigger 억제 확인 | E24: 상 | H24: -
A25: 23 | B25: Replicat | C25: Replicat ABEND 이력 | D25: VIEW REPORT → ERROR 없음 | E25: 상 | H25: -
A26: 24 | B26: Trail File | C26: Trail File 용량 모니터링 | D26: Extract Trail 급증 여부 (LOB 복제 시 특히 주의) | E26: 중 | G26: ☁️ | H26: -
A27: 25 | B27: Trail File | C27: Trail File 보존 정책 | D27: OCI Object Storage 보존 기간 설정 확인 | E27: 하 | G27: ☁️ | H27: -
A28: 26 | B28: 상시운영 | C28: LAG 임계치 알람 설정 | D28: OCI GG 모니터링 → LAG Alert 30초 이하 설정 | E28: 중 | G28: ☁️ | H28: -
A29: 27 | B29: 상시운영 | C29: GGADMIN 계정 비밀번호 만료 | D29: 패스워드 만료 정책 확인 / 무제한 설정 권장 | E29: 중 | F29: ⚠️ | H29: -
A30: 28 | B30: 상시운영 | C30: OCI GG Deployment 자동 패치 | D30: OCI Console 자동 업데이트 정책 확인 | E30: 하 | G30: ☁️ | H30: -

Sheet 02_Static_Schema
A1: NO | B1: 객체 유형 | C1: 검증 항목 | D1: 검증 방법 / 확인 내용 | E1: 중요도 | F1: SE제약 | G1: 결과 | H1: 비고
A2: ▶ 정적 구조 검증 (Static Schema Validation) — 스키마·객체·DDL 구조 비교
A3: 1 | B3: Table | C3: 테이블 수 일치 | D3: DBA_TABLES 기준 소스/타겟 테이블 목록 비교 | E3: 상 | G3: -
A4: 2 | B4: Table | C4: 컬럼 수 및 순서 일치 | D4: DBA_TAB_COLUMNS 컬럼명·순서·데이터타입 비교 | E4: 상 | G4: -
A5: 3 | B5: Table | C5: 데이터 타입 일치 | D5: NUMBER·VARCHAR2·DATE·TIMESTAMP 타입 및 길이 비교 | E5: 상 | G5: -
A6: 4 | B6: Table | C6: NULL 허용 여부 일치 | D6: NULLABLE 속성 소스/타겟 비교 | E6: 중 | G6: -
A7: 5 | B7: Table | C7: DEFAULT 값 일치 | D7: DATA_DEFAULT 속성 비교 | E7: 중 | G7: -
A8: 6 | B8: Index | C8: 인덱스 수 및 이름 일치 | D8: DBA_INDEXES 목록 비교 | E8: 상 | G8: -
A9: 7 | B9: Index | C9: 인덱스 유형 일치 | D9: NORMAL/UNIQUE/FUNCTION-BASED/BITMAP 비교 | E9: 상 | F9: ⚠️ BITMAP은 SE 미지원 | G9: -
A10: 8 | B10: Index | C10: 인덱스 상태 (VALID) | D10: STATUS=VALID 여부 확인 (UNUSABLE 없음) | E10: 상 | G10: -
A11: 9 | B11: Index | C11: 인덱스 컬럼 구성 일치 | D11: DBA_IND_COLUMNS 컬럼·순서 비교 | E11: 중 | G11: -
A12: 10 | B12: Constraint | C12: PK 제약 일치 | D12: DBA_CONSTRAINTS TYPE='P' 목록 비교 | E12: 상 | G12: -
A13: 11 | B13: Constraint | C13: FK 제약 일치 및 활성화 | D13: TYPE='R' + STATUS=ENABLED 확인 | E13: 상 | G13: -
A14: 12 | B14: Constraint | C14: UNIQUE 제약 일치 | D14: TYPE='U' 목록 및 STATUS 비교 | E14: 중 | G14: -
A15: 13 | B15: Constraint | C15: CHECK 제약 일치 | D15: TYPE='C' SEARCH_CONDITION 비교 | E15: 중 | G15: -
A16: 14 | B16: Constraint | C16: NOT NULL 일치 | D16: 컬럼 레벨 NOT NULL DBA_CONSTRAINTS 비교 | E16: 중 | G16: -
A17: 15 | B17: Constraint | C17: DISABLED 제약 없음 | D17: STATUS != 'DISABLED' 전체 확인 | E17: 상 | G17: -
A18: 16 | B18: View | C18: 뷰 수 및 이름 일치 | D18: DBA_VIEWS 목록 비교 | E18: 중 | G18: -
A19: 17 | B19: View | C19: 뷰 DDL(TEXT) 일치 | D19: VIEW TEXT 소스/타겟 비교 | E19: 중 | G19: -
A20: 18 | B20: View | C20: 뷰 컴파일 상태 VALID | D20: DBA_OBJECTS STATUS=VALID 확인 | E20: 중 | G20: -
A21: 19 | B21: Sequence | C21: 시퀀스 목록 일치 | D21: DBA_SEQUENCES 목록 비교 | E21: 상 | G21: -
A22: 20 | B22: Sequence | C22: INCREMENT/MIN/MAX/CACHE 일치 | D22: 시퀀스 속성값 비교 | E22: 상 | G22: -
A23: 21 | B23: Sequence | C23: 타겟 LAST_NUMBER ≥ 소스 MAX | D23: 시퀀스 현재값 Gap 안전 마진 확인 | E23: 상 | F23: ⚠️ CACHE로 인한 Gap 필수 확인 | G23: -
A24: 22 | B24: Synonym | C24: Public/Private Synonym 목록 | D24: DBA_SYNONYMS 소스/타겟 비교 | E24: 중 | G24: -
A25: 23 | B25: Synonym | C25: Synonym 참조 객체 존재 | D25: OBJECT_NAME 타겟에 실제 존재 여부 | E25: 중 | G25: -
A26: 24 | B26: Procedure/Function | C26: 객체 수 일치 | D26: DBA_PROCEDURES 목록 비교 | E26: 중 | G26: -
A27: 25 | B27: Procedure/Function | C27: 컴파일 상태 VALID | D27: DBA_OBJECTS STATUS=VALID (INVALID 0건) | E27: 상 | G27: -
A28: 26 | B28: Procedure/Function | C28: DDL 소스 일치 | D28: DBA_SOURCE TEXT 비교 | E28: 중 | G28: -
A29: 27 | B29: Package | C29: Package/Body 목록 일치 | D29: DBA_OBJECTS TYPE IN ('PACKAGE','PACKAGE BODY') | E29: 중 | G29: -
A30: 28 | B30: Package | C30: Package 컴파일 상태 | D30: STATUS=VALID 확인 | E30: 상 | G30: -
A31: 29 | B31: User/Role | C31: 사용자 목록 일치 | D31: DBA_USERS 비교 (시스템 계정 제외) | E31: 상 | G31: -
A32: 30 | B32: User/Role | C32: 롤 부여 현황 일치 | D32: DBA_ROLE_PRIVS 비교 | E32: 상 | G32: -
A33: 31 | B33: User/Role | C33: 시스템 권한 일치 | D33: DBA_SYS_PRIVS 비교 | E33: 상 | G33: -
A34: 32 | B34: User/Role | C34: 객체 권한 일치 | D34: DBA_TAB_PRIVS 비교 | E34: 중 | G34: -
A35: 33 | B35: Tablespace | C35: 테이블스페이스 목록 | D35: DBA_TABLESPACES 비교 | E35: 중 | G35: -
... A40: 38 | B40: INVALID 객체 | C40: INVALID 객체 재컴파일 | D40: DBMS_UTILITY.COMPILE_SCHEMA 실행 후 재확인 | E40: 상 | G40: -

Sheet 03_Data_Validation
A1: NO | B1: 검증 유형 | C1: 검증 항목 | D1: 검증 방법 / SQL 포인트 | E1: 중요도 | F1: SE제약 | G1: OCI GG | H1: 결과 | I1: 비고
A2: ▶ 데이터 정합성 검증 (Data Validation) — Row Count·Checksum·샘플·LOB·특수 데이터
A3: 1 | B3: Row Count | C3: 전체 테이블 Row Count 일치 | D3: DBA_TABLES 기준 전체 테이블 COUNT(*) 비교 | E3: 상 | H3: -
A4: 2 | B4: Row Count | C4: 대용량 테이블 별도 검증 | D4: 1억 건 이상 테이블 파티션 단위 분할 비교 | E4: 상 | H4: -
A5: 3 | B5: Row Count | C5: 마이그레이션 중 발생 건수 | D5: SCN 고정 후 소스 카운트 vs 타겟 비교 | E5: 상 | G5: ☁️ | H5: -
A6: 4 | B6: Checksum | C6: ORA_HASH 집계 비교 | D6: SUM(ORA_HASH(PK||col…)) 소스/타겟 동일 쿼리 비교 | E6: 상 | H6: -
A7: 5 | B7: Checksum | C7: 핵심 테이블 컬럼 집계 비교 | D7: SUM/MIN/MAX/AVG 숫자형 컬럼 집계값 비교 | E7: 상 | H7: -
A8: 6 | B8: Checksum | C8: Distinct Count 비교 | D8: 주요 컬럼 COUNT(DISTINCT) 소스/타겟 비교 | E8: 중 | H8: -
A9: 7 | B9: 샘플 데이터 | C9: PK 기준 행 단위 비교 | D9: PK 값 기준 소스/타겟 컬럼값 직접 비교 (상위 1000건) | E9: 중 | H9: -
A10: 8 | B10: 샘플 데이터 | C10: 최신 데이터 비교 | D10: MAX(updated_date) 기준 최근 100건 비교 | E10: 중 | H10: -
A11: 9 | B11: 샘플 데이터 | C11: NULL 비율 비교 | D11: 컬럼별 NULL COUNT 소스/타겟 비교 | E11: 중 | H11: -
A12: 10 | B12: LOB | C12: LOB 컬럼 건수 일치 | D12: CLOB/BLOB/NCLOB 포함 테이블 Row Count 비교 | E12: 상 | G12: ☁️ | H12: -
A13: 11 | B13: LOB | C13: LOB 총 SIZE 비교 | D13: SUM(DBMS_LOB.GETLENGTH) 소스/타겟 비교 | E13: 상 | G13: ☁️ | H13: -
A14: 12 | B14: LOB | C14: LOB MD5 해시 샘플 검증 | D14: DBMS_CRYPTO.HASH(MD5) 샘플 비교 | E14: 중 | H14: -
A15: 13 | B15: LOB | C15: EMPTY_LOB vs NULL 처리 일관성 | D15: EMPTY_CLOB()·EMPTY_BLOB()과 NULL 구분 확인 | E15: 중 | F15: ⚠️ | H15: -
A16: 14 | B16: LOB | C16: BasicFile vs SecureFile 전환 확인 | D16: DBA_LOBS.SECUREFILE 속성 타겟 확인 | E16: 중 | G16: ☁️ | H16: -
A17: 15 | B17: 데이터 타입 | C17: DATE 타입 시간 정보 손실 | D17: DATE 컬럼 HH24:MI:SS 포함 여부 확인 | E17: 중 | H17: -
A18: 16 | B18: 데이터 타입 | C18: TIMESTAMP WITH TIME ZONE | D18: NLS_TIMESTAMP_TZ_FORMAT 소스/타겟 일치 확인 | E18: 상 | H18: -
A19: 17 | B19: 데이터 타입 | C19: NUMBER 정밀도 비교 | D19: PRECISION·SCALE 소스/타겟 동일 여부 | E19: 중 | H19: -
A20: 18 | B20: 데이터 타입 | C20: CHAR vs VARCHAR2 패딩 | D20: CHAR 타입 공백 패딩 데이터 비교 | E20: 하 | H20: -
A21: 19 | B21: 데이터 타입 | C21: XMLTYPE 컬럼 | D21: XMLTYPE 저장방식(Object-Relational/CLOB) 확인 | E21: 중 | F21: ⚠️ | H21: -
A22: 20 | B22: 데이터 타입 | C22: ROWID 의존 로직 | D22: ROWID 사용 쿼리·프로시저 타겟 무효화 확인 | E22: 상 | H22: -
A23: 21 | B23: NLS | C23: NLS_CHARACTERSET 일치 | D23: AL32UTF8 등 문자셋 소스/타겟 동일 확인 | E23: 상 | H23: -
A24: 22 | B24: NLS | C24: NLS_DATE_FORMAT 일치 | D24: DATE 출력 포맷 소스/타겟 동일 확인 | E24: 중 | H24: -
A25: 23 | B25: NLS | C25: 한글/특수문자 깨짐 없음 | D25: 멀티바이트 문자 샘플 데이터 육안 확인 | E25: 중 | H25: -
A26: 24 | B26: 참조 무결성 | C26: Orphan Row 없음 | D26: FK 참조 부모 없는 자식 레코드 확인 | E26: 상 | H26: -
A27: 25 | B27: 참조 무결성 | C27: FK DISABLED 후 데이터 적재 여부 | D27: FK DISABLED 상태로 적재 시 무결성 오류 데이터 | E27: 상 | H27: -

Sheet 04_Special_Objects
A1: NO | B1: 객체 유형 | C1: 단계 | D1: 검증/확인 항목 | E1: 중요도 | F1: SE⚠️ | G1: OCI☁️ | H1: 결과 | I1: 비고
A2: ▶ 특수 객체 검증 — MV·Trigger·DB Link·DBMS_JOB·Partition·DDL Replication
A3: 1 | B3: MV | C3: Pre-Check | D3: 소스 MV 목록 및 REFRESH 방식 파악 (COMPLETE/FAST/FORCE) | E3: 상 | H3: -
A4: 2 | B4: MV | C4: Pre-Check | D4: MV Log 존재 여부 (FAST REFRESH 가능 여부) | E4: 상 | H4: -
A5: 3 | B5: MV | C5: Pre-Check | D5: MV STALENESS 상태 (FRESH/STALE 확인) | E5: 중 | H5: -
A6: 4 | B6: MV | C6: Validation | D6: MV 컨테이너 테이블 Row Count 소스/타겟 비교 | E6: 상 | H6: -
A7: 5 | B7: MV | C7: Validation | D7: 타겟 MV 재생성 완료 여부 | E7: 상 | G7: ☁️ | H7: -
A8: 6 | B8: MV | C8: Validation | D8: 타겟 MV REFRESH 정상 실행 여부 | E8: 상 | H8: -
A9: 7 | B9: MV | C9: Caution | D9: OCI GG는 MV 자체 복제 불가 → 타겟 재생성 필수 | E9: 상 | G9: ☁️ | H9: -
A10: 8 | B10: MV | C10: Caution | D10: 상시운영 중 MV STALE 시 REFRESH 주기 재설정 | E10: 중 | H10: -
A11: 9 | B11: Trigger | C11: Pre-Check | D11: 소스 Trigger 전체 DDL 추출 및 목록화 | E11: 중 | H11: -
A12: 10 | B12: Trigger | C12: Pre-Check | D12: INSTEAD OF Trigger (View 기반) 별도 식별 | E12: 중 | H12: -
A13: 11 | B13: Trigger | C13: Migration | D13: 복제 중 타겟 Trigger DISABLED 확인 | E13: 상 | H13: -
A14: 12 | B14: Trigger | C14: Migration | D14: SUPPRESSTRIGGERS 파라미터 적용 확인 | E14: 상 | G14: ☁️ | H14: -
A15: 13 | B15: Trigger | C15: Validation | D15: 복제 완료 후 Trigger ENABLED 재활성화 | E15: 상 | H15: -
A16: 14 | B16: Trigger | C16: Validation | D16: 이중 DML 발생 데이터 오염 여부 확인 | E16: 상 | H16: -
A17: 15 | B17: Trigger | C17: Caution | D17: 상시운영 중 GGADMIN 세션 Trigger 예외 처리 로직 확인 | E17: 상 | F17: ⚠️ | H17: -
A18: 16 | B18: DB Link | C18: Pre-Check | D18: 소스 DB Link 전체 목록 (Public/Private) 추출 | E18: 중 | H18: -
A19: 17 | B19: DB Link | C19: Pre-Check | D19: DB Link 의존 객체 (View/Proc) 식별 | E19: 중 | H19: -
A20: 18 | B20: DB Link | C20: Migration | D20: 타겟 네트워크에서 원격 DB 접근 가능 여부 | E20: 상 | G20: ☁️ | H20: -
A21: 19 | B21: DB Link | C21: Migration | D21: TNS/EZConnect 문자열 타겟 환경 맞게 수정 | E21: 상 | G21: ☁️ | H21: -
A22: 20 | B22: DB Link | C22: Validation | D22: 타겟 DB Link 연결 테스트 통과 | E22: 상 | H22: -
A23: 21 | B23: DB Link | C23: Validation | D23: DB Link 의존 객체 재컴파일 후 VALID 확인 | E23: 중 | H23: -
A24: 22 | B24: DB Link | C24: Caution | D24: OCI GG는 DB Link 복제 미지원 → 수동 재생성 필수 | E24: 상 | G24: ☁️ | H24: -
A25: 23 | B25: DBMS_JOB | C25: Pre-Check | D25: 소스 DBMS_JOB 전체 목록 및 INTERVAL 표현식 추출 | E25: 상 | H25: -
A26: 24 | B26: DBMS_JOB | C26: Pre-Check | D26: 실행 중인 JOB 및 BROKEN 상태 JOB 식별 | E26: 중 | H26: -
A27: 25 | B27: DBMS_JOB | C27: Migration | D27: 마이그레이션 중 소스 JOB BROKEN 처리 (이중 실행 방지) | E27: 상 | H27: -
A28: 26 | B28: DBMS_JOB | C28: Migration | D28: DBMS_SCHEDULER로 전환 매핑 작업 완료 | E28: 상 | F28: ⚠️ SE에서 DBMS_JOB Deprecated | G28: ☁️ | H28: -
A29: 27 | B29: DBMS_JOB | C29: Validation | D29: 타겟 DBMS_SCHEDULER JOB 생성 및 실행 확인 | E29: 상 | H29: -
A30: 28 | B30: DBMS_JOB | C30: Validation | D30: 실행 주기 소스 INTERVAL과 동일 여부 | E30: 중 | H30: -
A31: 29 | B31: DBMS_JOB | C31: Caution | D31: 상시운영 중 DBA_SCHEDULER_JOB_LOG 정기 모니터링 | E31: 중 | G31: ☁️ | H31: -
A32: 30 | B32: Sequence | C32: Pre-Check | D32: 전체 Sequence 목록 및 속성 추출 | E32: 상 | H32: -
A33: 31 | B33: Sequence | C33: Migration | D33: OCI GG SEQUENCE 파라미터 설정 확인 | E33: 상 | G33: ☁️ | H33: -
A34: 32 | B34: Sequence | C34: Validation | D34: 타겟 LAST_NUMBER ≥ 소스 LAST_NUMBER + CACHE_SIZE | E34: 상 | F34: ⚠️ CACHE Gap 필수 확인 | H34: -
A35: 33 | B35: Sequence | C35: Caution | D35: 상시운영 중 Sequence Gap 누적 → Cut-over 시 재설정 | E35: 상 | F35: ⚠️ | G35: ☁️ | H35: -
A36: 34 | B36: Partition Table | C36: Pre-Check | D36: 파티션 테이블 목록 및 파티션 유형 파악 | E36: 중 | H36: -
A37: 35 | B37: Partition Table | C37: Pre-Check | D37: 파티션 키 컬럼 및 파티션 수 확인 | E37: 중 | H37: -
A38: 36 | B38: Partition Table | C38: Validation | D38: 파티션별 Row Count 비교 | E38: 상 | H38: -
A39: 37 | B39: Partition Table | C39: Validation | D39: 파티션 Pruning 정상 동작 여부 | E39: 중 | H39: -
A40: 38 | B40: Partition Table | C40: Caution | D40: OCI GG 파티션 테이블 복제 시 Supplemental Log 필수 | E40: 상 | F40: ⚠️ | G40: ☁️ | H40: -
...

Sheet 05_Migration_Caution
A1: NO | B1: 구분 | C1: 항목 | D1: 상세 내용 | E1: 중요도 | F1: 태그 | G1: 조치 상태
A2: ▶ 마이그레이션 주의사항 & SE 제약 / OCI GG 특이사항 / 상시운영 포인트
A3: 1 | B3: SE 제약 | C3: GoldenGate 활성화 | D3: ENABLE_GOLDENGATE_REPLICATION=TRUE 수동 설정 필수 (SE 기본 FALSE) | E3: 상 | F3: ⚠️SE | G3: 미완료
A4: 2 | B4: SE 제약 | C4: Supplemental Logging | D4: SE는 자동 활성화 안됨. PK 없는 테이블 ALL COLUMNS 로깅 수동 설정 | E4: 상 | F4: ⚠️SE | G4: 미완료
A5: 3 | B5: SE 제약 | C5: Streams Pool 메모리 | D5: SGA 내 Streams Pool 수동 설정 필요 (STREAMS_POOL_SIZE) | E5: 중 | F5: ⚠️SE | G5: 미완료
A6: 4 | B6: SE 제약 | C6: DDL Replication 제한 | D6: SE는 일부 DDL 복제 미지원. 지원 DDL 유형 사전 확인 필수 | E6: 상 | F6: ⚠️SE | G6: 미완료
A7: 5 | B7: SE 제약 | C7: BITMAP Index 미지원 | D7: SE는 BITMAP Index 생성 불가 → 타겟에서 일반 Index로 대체 | E7: 중 | F7: ⚠️SE | G7: 미완료
A8: 6 | B8: SE 제약 | C8: DBMS_JOB Deprecated | D8: SE 19c에서 DBMS_JOB → DBMS_SCHEDULER 전환 권장 | E8: 중 | F8: ⚠️SE | G8: 미완료
A9: 7 | B9: OCI GG | C9: RDS Redo Log 보존 | D9: AWS RDS는 기본 보존 1h → 최소 24h로 연장 필수 (Extract 지연 대비) | E9: 상 | F9: ☁️OCI | G9: 미완료
A10: 8 | B10: OCI GG | C10: Cloud 버전 DDL 제약 | D10: On-Premise GG 대비 DDL Replication 지원 범위 상이. 릴리즈 노트 확인 | E10: 상 | F10: ☁️OCI | G10: 미완료
A11: 9 | B11: OCI GG | C11: Trail File 저장소 | D11: OCI Object Storage 기반 Trail. 비용 및 보존 정책 사전 설정 | E11: 중 | F11: ☁️OCI | G11: 미완료
A12: 10 | B12: OCI GG | C12: 네트워크 지연 | D12: RDS(AWS Tokyo) → OCI GG(OCI Tokyo) 구간 Latency LAG 영향 | E12: 상 | F12: ☁️OCI | G12: 미완료
A13: 11 | B13: OCI GG | C13: Deployment 버전 호환 | D13: Oracle 19c SE 지원 OCI GG 버전 확인. 자동 업데이트 정책 관리 | E13: 중 | F13: ☁️OCI | G13: 미완료
A14: 12 | B14: OCI GG | C14: MV 복제 미지원 | D14: MV 자체는 OCI GG 복제 불가 → 타겟에서 수동 재생성 후 REFRESH | E14: 상 | F14: ☁️OCI | G14: 미완료
... A28: 26 | B28: 상시운영 | C28: 신규 테이블 GG 포함 | D28: 신규 테이블 생성 시 Supplemental Log 자동 추가 절차 수립 | E28: 중 | F28: ⚠️SE | G28: 미완료

Sheet 06_Result_Dashboard
B1: DB 정합성 검증 결과 대시보드
B4: 검증 영역 | C4: 전체 항목 | D4: PASS | E4: FAIL | F4: WARN | G4: 판정
B5: ① GG 프로세스 | C5: 28 | D5: =COUNTIF('01_GG_Process'!H3:H200,"PASS") -> 0 | E5: =COUNTIF('01_GG_Process'!H3:H200,"FAIL") -> 0 | F5: =COUNTIF('01_GG_Process'!H3:H200,"WARN") -> 0 | G5: =IF(E5>0,"❌ FAIL",IF(F5>0,"⚠️ WARN","✅ PASS")) -> ✅ PASS
B6: ② 정적 구조 검증 | C6: 38 | D6: =COUNTIF('02_Static_Schema'!H3:H200,"PASS") -> 0 | E6: =COUNTIF('02_Static_Schema'!H3:H200,"FAIL") -> 0 | F6: =COUNTIF('02_Static_Schema'!H3:H200,"WARN") -> 0 | G6: =IF(E6>0,"❌ FAIL",IF(F6>0,"⚠️ WARN","✅ PASS")) -> ✅ PASS
B7: ③ 데이터 정합성 | C7: 27 | D7: =COUNTIF('03_Data_Validation'!H3:H198,"PASS") -> 0 | E7: =COUNTIF('03_Data_Validation'!H3:H198,"FAIL") -> 0 | F7: =COUNTIF('03_Data_Validation'!H3:H198,"WARN") -> 0 | G7: =IF(E7>0,"❌ FAIL",IF(F7>0,"⚠️ WARN","✅ PASS")) -> ✅ PASS
B8: ④ 특수 객체 | C8: 43 | D8: =COUNTIF('04_Special_Objects'!H3:H200,"PASS") -> 0 | E8: =COUNTIF('04_Special_Objects'!H3:H200,"FAIL") -> 0 | F8: =COUNTIF('04_Special_Objects'!H3:H200,"WARN") -> 0 | G8: =IF(E8>0,"❌ FAIL",IF(F8>0,"⚠️ WARN","✅ PASS")) -> ✅ PASS
B9: 합계 | C9: =SUM(C5:C8) -> 136 | D9: =SUM(D5:D8) -> 0 | E9: =SUM(E5:E8) -> 0 | F9: =SUM(F5:F8) -> 0 | G9: =IF(E9>0,"❌ FAIL – 즉시 조치",IF(F9>0,"⚠️ WARN – 검토 필요","✅ PASS – Go 승인")) -> ✅ PASS – Go 승인
B12: ★ OCI GG 상시 운영 Top 10 주의사항
B13: 1. Extract / Replicat LAG 상시 모니터링 | C13: LAG > 30초 알람 설정 필수 | G13: 상
B14: 2. ⚠️SE PK 없는 테이블 ALL COLUMNS Logging | C14: Supplemental Log 누락 시 Extract ABEND | G14: 상
B15: 3. Sequence GAP 누적 관리 | C15: Cut-over 시 타겟 Sequence 소스 MAX + 여유분 재설정 | G15: 상
B16: 4. Trigger 이중 실행 방지 | C16: GGADMIN 세션 대상 Trigger DISABLE 로직 확인 | G16: 상
B17: 5. ☁️OCI DDL Replication ABEND 관리 | C17: 지원 외 DDL 발생 시 수동 처리 절차 사전 수립 | G17: 상
B18: 6. ☁️OCI RDS Redo Log 보존 기간 관리 | C18: 최소 24h 이상 유지 (Extract 장애 복구 대비) | G18: 상
B19: 7. GGADMIN 비밀번호 만료 모니터링 | C19: 만료 시 Extract 즉시 ABEND → 갱신 절차 수립 | G19: 중
B20: 8. LOB 컬럼 Trail File 용량 급증 | C20: LOB 변경 빈발 테이블 Trail 크기 모니터링 | G20: 중
B21: 9. Constraint DISABLED 상태 정기 점검 | C21: FK/CHECK Disabled 상태 방치 시 무결성 오류 | G21: 중
B22: 10. NLS 파라미터 / 타임존 변경 금지 | C22: 운영 중 NLS_CHARACTERSET 변경 절대 금지 정책 | G22: 상
